<?xml version="1.0" ?>
<!-- =================================================================================== -->
<!-- |    This document was autogenerated by xacro from gazebo_rml_63_gripper.urdf.xacro | -->
<!-- |    EDITING THIS FILE BY HAND IS NOT RECOMMENDED                                 | -->
<!-- =================================================================================== -->
<!-- Copyright (c) Qualcomm Technologies, Inc. and/or its subsidiaries.
SPDX-License-Identifier: BSD-3-Clause-Clear -->
<robot name="rml_63">
  <link name="arm_base_link">
    <inertial>
      <origin rpy="0 0 0" xyz="0.0014231 -0.00010178 0.050147"/>
      <mass value="0.66171"/>
      <inertia ixx="0.00099443" ixy="3.282E-06" ixz="-9.9964E-06" iyy="0.0010144" iyz="1.2811E-06" izz="0.00067929"/>
    </inertial>
    <visual>
      <origin rpy="0 0 0" xyz="0 0 0"/>
      <geometry>
        <mesh filename="file:///home/tengf/qrb_ros_simulation/install/qrb_ros_sim_description/share/qrb_ros_sim_description/meshes/rml_63_gripper_arm/base_link.STL"/>
      </geometry>
      <material name="">
        <color rgba="1 1 1 1"/>
      </material>
    </visual>
    <collision>
      <origin rpy="0 0 0" xyz="0 0 0"/>
      <geometry>
        <mesh filename="file:///home/tengf/qrb_ros_simulation/install/qrb_ros_sim_description/share/qrb_ros_sim_description/meshes/rml_63_gripper_arm/base_link.STL"/>
      </geometry>
    </collision>
  </link>
  <link name="link1">
    <inertial>
      <origin rpy="0 0 0" xyz="-0.043281 -0.0072256 -0.012694"/>
      <mass value="0.89496"/>
      <inertia ixx="0.0010156" ixy="-0.00026764" ixz="0.00045014" iyy="0.0024107" iyz="6.0996E-05" izz="0.0022755"/>
    </inertial>
    <visual>
      <origin rpy="0 0 0" xyz="0 0 0"/>
      <geometry>
        <mesh filename="file:///home/tengf/qrb_ros_simulation/install/qrb_ros_sim_description/share/qrb_ros_sim_description/meshes/rml_63_gripper_arm/link1.STL"/>
      </geometry>
      <material name="">
        <color rgba="1 1 1 1"/>
      </material>
    </visual>
    <collision>
      <origin rpy="0 0 0" xyz="0 0 0"/>
      <geometry>
        <mesh filename="file:///home/tengf/qrb_ros_simulation/install/qrb_ros_sim_description/share/qrb_ros_sim_description/meshes/rml_63_gripper_arm/link1.STL"/>
      </geometry>
    </collision>
  </link>
  <joint name="joint1" type="revolute">
    <origin rpy="0 0 0" xyz="0 0 0.1720"/>
    <parent link="arm_base_link"/>
    <child link="link1"/>
    <dynamics damping="0.5" friction="0.5"/>
    <axis xyz="0 0 1"/>
    <limit effort="60" lower="-3.106" upper="3.106" velocity="3.14"/>
  </joint>
  <link name="link2">
    <inertial>
      <origin rpy="0 0 0" xyz="0.17388 3.639E-07 -0.089966"/>
      <mass value="1.5679"/>
      <inertia ixx="0.0010615" ixy="-7.3371E-08" ixz="-0.00025488" iyy="0.03035" iyz="-1.6148E-08" izz="0.030485"/>
    </inertial>
    <visual>
      <origin rpy="0 0 0" xyz="0 0 0"/>
      <geometry>
        <mesh filename="file:///home/tengf/qrb_ros_simulation/install/qrb_ros_sim_description/share/qrb_ros_sim_description/meshes/rml_63_gripper_arm/link2.STL"/>
      </geometry>
      <material name="">
        <color rgba="1 1 1 1"/>
      </material>
    </visual>
    <collision>
      <origin rpy="0 0 0" xyz="0 0 0"/>
      <geometry>
        <mesh filename="file:///home/tengf/qrb_ros_simulation/install/qrb_ros_sim_description/share/qrb_ros_sim_description/meshes/rml_63_gripper_arm/link2.STL"/>
      </geometry>
    </collision>
  </link>
  <joint name="joint2" type="revolute">
    <origin rpy="0 -1.5708 -1.5708" xyz="-0.086 0 0"/>
    <parent link="link1"/>
    <child link="link2"/>
    <dynamics damping="0.5" friction="0.5"/>
    <axis xyz="0 0 1"/>
    <limit effort="60" lower="-3.106" upper="3.106" velocity="3.14"/>
  </joint>
  <link name="link3">
    <inertial>
      <origin rpy="0 0 0" xyz="0.035968 -0.020568 -0.0048526"/>
      <mass value="0.67539"/>
      <inertia ixx="0.00091144" ixy="0.00043238" ixz="-0.0001205" iyy="0.0012128" iyz="6.6376E-05" izz="0.0015231"/>
    </inertial>
    <visual>
      <origin rpy="0 0 0" xyz="0 0 0"/>
      <geometry>
        <mesh filename="file:///home/tengf/qrb_ros_simulation/install/qrb_ros_sim_description/share/qrb_ros_sim_description/meshes/rml_63_gripper_arm/link3.STL"/>
      </geometry>
      <material name="">
        <color rgba="1 1 1 1"/>
      </material>
    </visual>
    <collision>
      <origin rpy="0 0 0" xyz="0 0 0"/>
      <geometry>
        <mesh filename="file:///home/tengf/qrb_ros_simulation/install/qrb_ros_sim_description/share/qrb_ros_sim_description/meshes/rml_63_gripper_arm/link3.STL"/>
      </geometry>
    </collision>
  </link>
  <joint name="joint3" type="revolute">
    <origin rpy="0 0 1.5708" xyz="0.38 0 -0.00030011"/>
    <parent link="link2"/>
    <child link="link3"/>
    <dynamics damping="0.5" friction="0.5"/>
    <axis xyz="0 0 1"/>
    <limit effort="30" lower="-3.106" upper="2.53" velocity="3.92"/>
  </joint>
  <link name="link4">
    <inertial>
      <origin rpy="0 0 0" xyz="-2.0098E-06 -0.033559 -0.18296"/>
      <mass value="0.69687"/>
      <inertia ixx="0.0085449" ixy="4.7796E-08" ixz="-1.0943E-08" iyy="0.0080043" iyz="0.0020032" izz="0.00084216"/>
    </inertial>
    <visual>
      <origin rpy="0 0 0" xyz="0 0 0"/>
      <geometry>
        <mesh filename="file:///home/tengf/qrb_ros_simulation/install/qrb_ros_sim_description/share/qrb_ros_sim_description/meshes/rml_63_gripper_arm/link4.STL"/>
      </geometry>
      <material name="">
        <color rgba="1 1 1 1"/>
      </material>
    </visual>
    <collision>
      <origin rpy="0 0 0" xyz="0 0 0"/>
      <geometry>
        <mesh filename="file:///home/tengf/qrb_ros_simulation/install/qrb_ros_sim_description/share/qrb_ros_sim_description/meshes/rml_63_gripper_arm/link4.STL"/>
      </geometry>
    </collision>
  </link>
  <joint name="joint4" type="revolute">
    <origin rpy="1.5708 0 0" xyz="0.069 -0.405 0.00029958"/>
    <parent link="link3"/>
    <child link="link4"/>
    <dynamics damping="0.5" friction="0.5"/>
    <axis xyz="0 0 1"/>
    <limit effort="10" lower="-3.106" upper="3.106" velocity="3.92"/>
  </joint>
  <link name="link5">
    <inertial>
      <origin rpy="0 0 0" xyz="-1.5679E-07 0.02862 -0.0062118"/>
      <mass value="0.34759"/>
      <inertia ixx="0.00049457" ixy="-1.0235E-08" ixz="-1.8949E-09" iyy="0.00019706" iyz="-6.3439E-05" izz="0.00044565"/>
    </inertial>
    <visual>
      <origin rpy="0 0 0" xyz="0 0 0"/>
      <geometry>
        <mesh filename="file:///home/tengf/qrb_ros_simulation/install/qrb_ros_sim_description/share/qrb_ros_sim_description/meshes/rml_63_gripper_arm/link5.STL"/>
      </geometry>
      <material name="">
        <color rgba="1 1 1 1"/>
      </material>
    </visual>
    <collision>
      <origin rpy="0 0 0" xyz="0 0 0"/>
      <geometry>
        <mesh filename="file:///home/tengf/qrb_ros_simulation/install/qrb_ros_sim_description/share/qrb_ros_sim_description/meshes/rml_63_gripper_arm/link5.STL"/>
      </geometry>
    </collision>
  </link>
  <joint name="joint5" type="revolute">
    <origin rpy="1.5708 0 3.1416" xyz="0 0 0"/>
    <parent link="link4"/>
    <child link="link5"/>
    <dynamics damping="0.5" friction="0.5"/>
    <axis xyz="0 0 1"/>
    <limit effort="10" lower="-3.106" upper="3.106" velocity="3.92"/>
  </joint>
  <link name="link6">
    <inertial>
      <origin rpy="0 0 0" xyz="-0.0006163 0.00034085 -0.01449"/>
      <mass value="0.077104"/>
      <inertia ixx="2.2947E-05" ixy="-1.3061E-06" ixz="1.1202E-07" iyy="2.1475E-05" iyz="-5.1151E-08" izz="3.4243E-05"/>
    </inertial>
    <visual>
      <origin rpy="0 0 0" xyz="0 0 0"/>
      <geometry>
        <mesh filename="file:///home/tengf/qrb_ros_simulation/install/qrb_ros_sim_description/share/qrb_ros_sim_description/meshes/rml_63_gripper_arm/link6.STL"/>
      </geometry>
      <material name="">
        <color rgba="1 1 1 1"/>
      </material>
    </visual>
    <collision>
      <origin rpy="0 0 0" xyz="0 0 0"/>
      <geometry>
        <mesh filename="file:///home/tengf/qrb_ros_simulation/install/qrb_ros_sim_description/share/qrb_ros_sim_description/meshes/rml_63_gripper_arm/link6.STL"/>
      </geometry>
    </collision>
  </link>
  <joint name="joint6" type="revolute">
    <origin rpy="1.5708 0 3.1416" xyz="0 0.115 0"/>
    <parent link="link5"/>
    <child link="link6"/>
    <dynamics damping="0.5" friction="0.5"/>
    <axis xyz="0 0 1"/>
    <limit effort="10" lower="-6.28" upper="6.28" velocity="3.92"/>
  </joint>
  <link name="link7">
    <inertial>
      <origin rpy="0 0 0" xyz="0.04582 -2.3076E-07 -0.005454"/>
      <mass value="0.051307"/>
      <inertia ixx="1.5914E-05" ixy="4.818E-10" ixz="1.4306E-07" iyy="8.6532E-05" iyz="-1.6535E-11" izz="0.00010189"/>
    </inertial>
    <visual>
      <origin rpy="0 0 3.1416" xyz="0 0 0"/>
      <geometry>
        <mesh filename="file:///home/tengf/qrb_ros_simulation/install/qrb_ros_sim_description/share/qrb_ros_sim_description/meshes/rml_63_gripper_arm/link7.STL"/>
      </geometry>
      <material name="">
        <color rgba="1 1 1 1"/>
      </material>
    </visual>
    <collision>
      <origin rpy="0 0 3.1416" xyz="0 0 0"/>
      <geometry>
        <mesh filename="file:///home/tengf/qrb_ros_simulation/install/qrb_ros_sim_description/share/qrb_ros_sim_description/meshes/rml_63_gripper_arm/link7.STL"/>
      </geometry>
    </collision>
  </link>
  <joint name="joint7" type="fixed">
    <origin rpy="0 0 3.1416" xyz="0 0 0.008"/>
    <parent link="link6"/>
    <child link="link7"/>
    <axis xyz="0 0 0"/>
  </joint>
  <link name="link8"/>
  <joint name="joint8" type="fixed">
    <origin rpy="0 0 0" xyz="-0.01 0 0.043"/>
    <parent link="link7"/>
    <child link="link8"/>
    <axis xyz="0 0 0"/>
  </joint>
  <joint name="joint00" type="fixed">
    <parent link="link8"/>
    <child link="Link00"/>
    <origin rpy="0 -1.5708 0" xyz="0 0 0"/>
  </joint>
  <link name="Link00">
    <inertial>
      <origin rpy="0 0 0" xyz="0.00339303654278191 -2.1205433560656E-05 -0.0099185365078758"/>
      <mass value="0.105853592307918"/>
      <inertia ixx="3.93795927851199E-05" ixy="-8.7395226509728E-08" ixz="5.91928672040786E-07" iyy="0.000106376720416166" iyz="-1.82858764303774E-10" izz="0.000125852616063213"/>
    </inertial>
    <visual>
      <origin rpy="0 0 0" xyz="0 0 0"/>
      <geometry>
        <mesh filename="file:///home/tengf/qrb_ros_simulation/install/qrb_ros_sim_description/share/qrb_ros_sim_description/meshes/rml_63_gripper_arm/Link00.STL"/>
      </geometry>
      <material name="">
        <color rgba="0.1 0.1 0.1 1"/>
      </material>
    </visual>
    <collision>
      <origin rpy="0 0 0" xyz="0 0 0"/>
      <geometry>
        <mesh filename="file:///home/tengf/qrb_ros_simulation/install/qrb_ros_sim_description/share/qrb_ros_sim_description/meshes/rml_63_gripper_arm/Link00.STL"/>
      </geometry>
    </collision>
  </link>
  <link name="Link01">
    <inertial>
      <origin rpy="0 0 0" xyz="0.0164149658242926 9.75754915755189E-09 0.00898193900447147"/>
      <mass value="0.00647716099397792"/>
      <inertia ixx="2.95068972140683E-07" ixy="8.63208170411155E-13" ixz="-1.92008628754607E-09" iyy="1.69979619476872E-06" iyz="-1.99232397395103E-13" izz="1.45016449434989E-06"/>
    </inertial>
    <visual>
      <origin rpy="0 0 0" xyz="0 0 0"/>
      <geometry>
        <mesh filename="file:///home/tengf/qrb_ros_simulation/install/qrb_ros_sim_description/share/qrb_ros_sim_description/meshes/rml_63_gripper_arm/Link01.STL"/>
      </geometry>
      <material name="">
        <color rgba="0.1 0.1 0.1 1"/>
      </material>
    </visual>
    <collision>
      <origin rpy="0 0 0" xyz="0 0 0"/>
      <geometry>
        <mesh filename="file:///home/tengf/qrb_ros_simulation/install/qrb_ros_sim_description/share/qrb_ros_sim_description/meshes/rml_63_gripper_arm/Link01.STL"/>
      </geometry>
    </collision>
  </link>
  <joint name="joint01" type="revolute">
    <origin rpy="-3.0158E-16 -7.1586E-16 -0.30719" xyz="0.036 -0.04 -0.019"/>
    <parent link="Link00"/>
    <child link="Link01"/>
    <dynamics damping="0.1" friction="0.1"/>
    <axis xyz="0 0 1"/>
    <limit effort="1" lower="0" upper="1" velocity="3.14"/>
  </joint>
  <link name="Link11">
    <inertial>
      <origin rpy="0 0 0" xyz="0.011366555972498 0.0118642725662323 0.0060000073930068"/>
      <mass value="0.0127543420299361"/>
      <inertia ixx="5.68538478020233E-07" ixy="-2.68012262729007E-07" ixz="9.34125984931838E-13" iyy="1.45145776457487E-06" iyz="9.34355360561326E-13" izz="1.50564598220449E-06"/>
    </inertial>
    <visual>
      <origin rpy="0 0 0" xyz="0 0 0"/>
      <geometry>
        <mesh filename="file:///home/tengf/qrb_ros_simulation/install/qrb_ros_sim_description/share/qrb_ros_sim_description/meshes/rml_63_gripper_arm/Link11.STL"/>
      </geometry>
      <material name="">
        <color rgba="0.1 0.1 0.1 1"/>
      </material>
    </visual>
    <collision>
      <origin rpy="0 0 0" xyz="0 0 0"/>
      <geometry>
        <mesh filename="file:///home/tengf/qrb_ros_simulation/install/qrb_ros_sim_description/share/qrb_ros_sim_description/meshes/rml_63_gripper_arm/Link11.STL"/>
      </geometry>
    </collision>
  </link>
  <joint name="joint11" type="revolute">
    <origin rpy="5.0393E-16 5.6225E-16 0.30719" xyz="0.042 0 0.003"/>
    <parent link="Link01"/>
    <child link="Link11"/>
    <dynamics damping="0.1" friction="0.1"/>
    <axis xyz="0 0 1"/>
    <limit effort="1" lower="-1" upper="0" velocity="3.14"/>
  </joint>
  <link name="Link02">
    <inertial>
      <origin rpy="0 0 0" xyz="0.0164149658242926 9.75754915755189E-09 0.00898193900447147"/>
      <mass value="0.00647716099397793"/>
      <inertia ixx="2.95068972140683E-07" ixy="8.63208169650113E-13" ixz="-1.92008628755341E-09" iyy="1.69979619476872E-06" iyz="-1.99232397320157E-13" izz="1.45016449434989E-06"/>
    </inertial>
    <visual>
      <origin rpy="0 0 0" xyz="0 0 0"/>
      <geometry>
        <mesh filename="file:///home/tengf/qrb_ros_simulation/install/qrb_ros_sim_description/share/qrb_ros_sim_description/meshes/rml_63_gripper_arm/Link02.STL"/>
      </geometry>
      <material name="">
        <color rgba="0.1 0.1 0.1 1"/>
      </material>
    </visual>
    <collision>
      <origin rpy="0 0 0" xyz="0 0 0"/>
      <geometry>
        <mesh filename="file:///home/tengf/qrb_ros_simulation/install/qrb_ros_sim_description/share/qrb_ros_sim_description/meshes/rml_63_gripper_arm/Link02.STL"/>
      </geometry>
    </collision>
  </link>
  <joint name="joint02" type="revolute">
    <origin rpy="-2.6397E-16 3.7199E-16 0.30719" xyz="0.036 0.04 -0.019"/>
    <parent link="Link00"/>
    <child link="Link02"/>
    <dynamics damping="0.1" friction="0.1"/>
    <axis xyz="0 0 1"/>
    <limit effort="1" lower="-1" upper="0" velocity="3.14"/>
  </joint>
  <link name="Link22">
    <inertial>
      <origin rpy="0 0 0" xyz="-0.011366555972498 0.0118642725662323 -0.0060000073930068"/>
      <mass value="0.0127543420299362"/>
      <inertia ixx="5.68538478020238E-07" ixy="2.6801226272901E-07" ixz="9.34125986250171E-13" iyy="1.45145776457489E-06" iyz="-9.34355361631596E-13" izz="1.5056459822045E-06"/>
    </inertial>
    <visual>
      <origin rpy="0 0 0" xyz="0 0 0"/>
      <geometry>
        <mesh filename="file:///home/tengf/qrb_ros_simulation/install/qrb_ros_sim_description/share/qrb_ros_sim_description/meshes/rml_63_gripper_arm/Link22.STL"/>
      </geometry>
      <material name="">
        <color rgba="0.1 0.1 0.1 1"/>
      </material>
    </visual>
    <collision>
      <origin rpy="0 0 0" xyz="0 0 0"/>
      <geometry>
        <mesh filename="file:///home/tengf/qrb_ros_simulation/install/qrb_ros_sim_description/share/qrb_ros_sim_description/meshes/rml_63_gripper_arm/Link22.STL"/>
      </geometry>
    </collision>
  </link>
  <joint name="joint22" type="revolute">
    <origin rpy="-3.641E-16 2.4584E-16 2.8344" xyz="0.042 0 0.015"/>
    <parent link="Link02"/>
    <child link="Link22"/>
    <dynamics damping="0.1" friction="0.1"/>
    <axis xyz="0 0 1"/>
    <limit effort="1" lower="0" upper="1" velocity="3.14"/>
  </joint>
  <link name="camera_link">
    <inertial>
      <origin rpy="0 0 0" xyz="0.00277269933215555 -1.06084680351007E-05 0.012801025085723"/>
      <mass value="0.0186143499064346"/>
      <inertia ixx="1.38922229644605E-05" ixy="-4.74617876641156E-09" ixz="1.99175628166615E-08" iyy="1.70686808598814E-06" iyz="-7.18717290327325E-09" izz="1.31766831843134E-05"/>
    </inertial>
    <visual>
      <origin rpy="0 0 0" xyz="0 0 0"/>
      <geometry>
        <mesh filename="file:///home/tengf/qrb_ros_simulation/install/qrb_ros_sim_description/share/qrb_ros_sim_description/meshes/gemini335_336/camera_link.STL"/>
      </geometry>
      <material name="">
        <color rgba="1 1 1 1"/>
      </material>
    </visual>
    <collision>
      <origin rpy="0 0 0" xyz="0 0 0"/>
      <geometry>
        <mesh filename="file:///home/tengf/qrb_ros_simulation/install/qrb_ros_sim_description/share/qrb_ros_sim_description/meshes/gemini335_336/camera_link.STL"/>
      </geometry>
    </collision>
  </link>
  <link name="camera_bottom_screw_frame">
    <inertial>
      <origin rpy="0 0 0" xyz="0.00255168206289301 -0.00123934714960528 0.0118889875786098"/>
      <mass value="0.00564476880678651"/>
      <inertia ixx="3.07690693820862E-06" ixy="-1.85045956307764E-08" ixz="-9.2792327175816E-09" iyy="2.27632852811487E-07" iyz="1.65233162864392E-08" izz="2.93985735090777E-06"/>
    </inertial>
    <visual>
      <origin rpy="0 0 0" xyz="0 0 0"/>
      <geometry>
        <mesh filename="file:///home/tengf/qrb_ros_simulation/install/qrb_ros_sim_description/share/qrb_ros_sim_description/meshes/gemini335_336/camera_bottom_screw_frame.STL"/>
      </geometry>
      <material name="">
        <color rgba="0.792156862745098 0.819607843137255 0.933333333333333 1"/>
      </material>
    </visual>
    <collision>
      <origin rpy="0 0 0" xyz="0 0 0"/>
      <geometry>
        <mesh filename="file:///home/tengf/qrb_ros_simulation/install/qrb_ros_sim_description/share/qrb_ros_sim_description/meshes/gemini335_336/camera_bottom_screw_frame.STL"/>
      </geometry>
    </collision>
  </link>
  <joint name="camera_bottom_screw_frame_joint" type="fixed">
    <origin rpy="0 0 0" xyz="0 0 0"/>
    <parent link="camera_link"/>
    <child link="camera_bottom_screw_frame"/>
    <axis xyz="0 0 0"/>
  </joint>
  <link name="camera_infra_1_frame">
    <inertial>
      <origin rpy="0 0 0" xyz="-0.00158020887627678 -1.52683853303637E-08 -1.4860800305164E-07"/>
      <mass value="0.000453168790516429"/>
      <inertia ixx="4.34108781911687E-09" ixy="-3.69655517007001E-13" ixz="-1.45486421873185E-13" iyy="4.84012226840139E-09" iyz="1.92888940614786E-14" izz="4.84044260907388E-09"/>
    </inertial>
    <visual>
      <origin rpy="0 0 0" xyz="0 0 0"/>
      <geometry>
        <mesh filename="file:///home/tengf/qrb_ros_simulation/install/qrb_ros_sim_description/share/qrb_ros_sim_description/meshes/gemini335_336/camera_infra_1_frame.STL"/>
      </geometry>
      <material name="">
        <color rgba="0.501960784313725 0.250980392156863 0.250980392156863 1"/>
      </material>
    </visual>
    <collision>
      <origin rpy="0 0 0" xyz="0 0 0"/>
      <geometry>
        <mesh filename="file:///home/tengf/qrb_ros_simulation/install/qrb_ros_sim_description/share/qrb_ros_sim_description/meshes/gemini335_336/camera_infra_1_frame.STL"/>
      </geometry>
    </collision>
  </link>
  <joint name="camera_infra_1_joint" type="fixed">
    <origin rpy="0 0 0" xyz="0.01587 -0.025 0.0125"/>
    <parent link="camera_bottom_screw_frame"/>
    <child link="camera_infra_1_frame"/>
    <axis xyz="0 0 0"/>
  </joint>
  <link name="camera_infra_1_optical_frame">
    <inertial>
      <origin rpy="0 0 0" xyz="1.52683853338331E-08 1.48608003051636E-07 -0.00158020887627678"/>
      <mass value="0.000453168790516429"/>
      <inertia ixx="4.84012226840139E-09" ixy="1.92888940614797E-14" ixz="3.69655517006993E-13" iyy="4.84044260907388E-09" iyz="1.45486421873192E-13" izz="4.34108781911687E-09"/>
    </inertial>
    <visual>
      <origin rpy="0 0 0" xyz="0 0 0"/>
      <geometry>
        <mesh filename="file:///home/tengf/qrb_ros_simulation/install/qrb_ros_sim_description/share/qrb_ros_sim_description/meshes/gemini335_336/camera_infra_1_optical_frame.STL"/>
      </geometry>
      <material name="">
        <color rgba="0.501960784313725 0.250980392156863 0.250980392156863 1"/>
      </material>
    </visual>
    <collision>
      <origin rpy="0 0 0" xyz="0 0 0"/>
      <geometry>
        <mesh filename="file:///home/tengf/qrb_ros_simulation/install/qrb_ros_sim_description/share/qrb_ros_sim_description/meshes/gemini335_336/camera_infra_1_optical_frame.STL"/>
      </geometry>
    </collision>
  </link>
  <joint name="camera_infra_1_optical_joint" type="fixed">
    <origin rpy="-1.5707963267949 0 -1.5707963267949" xyz="0.01587 -0.025 0.0125"/>
    <parent link="camera_bottom_screw_frame"/>
    <child link="camera_infra_1_optical_frame"/>
    <axis xyz="0 0 0"/>
  </joint>
  <link name="camera_infra2_frame">
    <inertial>
      <origin rpy="0 0 0" xyz="-0.00158020887627678 -1.52683853303637E-08 -1.48608003050581E-07"/>
      <mass value="0.000453168790516429"/>
      <inertia ixx="4.34108781911687E-09" ixy="-3.69655517007898E-13" ixz="-1.45486421873762E-13" iyy="4.84012226840139E-09" iyz="1.92888940594506E-14" izz="4.84044260907389E-09"/>
    </inertial>
    <visual>
      <origin rpy="0 0 0" xyz="0 0 0"/>
      <geometry>
        <mesh filename="file:///home/tengf/qrb_ros_simulation/install/qrb_ros_sim_description/share/qrb_ros_sim_description/meshes/gemini335_336/camera_infra2_frame.STL"/>
      </geometry>
      <material name="">
        <color rgba="0.501960784313725 0.250980392156863 0.250980392156863 1"/>
      </material>
    </visual>
    <collision>
      <origin rpy="0 0 0" xyz="0 0 0"/>
      <geometry>
        <mesh filename="file:///home/tengf/qrb_ros_simulation/install/qrb_ros_sim_description/share/qrb_ros_sim_description/meshes/gemini335_336/camera_infra2_frame.STL"/>
      </geometry>
    </collision>
  </link>
  <joint name="camera_infra2_joint" type="fixed">
    <origin rpy="0 0 0" xyz="0.01587 0.025 0.0125"/>
    <parent link="camera_bottom_screw_frame"/>
    <child link="camera_infra2_frame"/>
    <axis xyz="0 0 0"/>
  </joint>
  <link name="camera_infra2_optical_frame">
    <inertial>
      <origin rpy="0 0 0" xyz="1.52683853268942E-08 1.4860800305058E-07 -0.00158020887627678"/>
      <mass value="0.000453168790516429"/>
      <inertia ixx="4.84012226840139E-09" ixy="1.92888940594538E-14" ixz="3.69655517007897E-13" iyy="4.84044260907389E-09" iyz="1.45486421873764E-13" izz="4.34108781911687E-09"/>
    </inertial>
    <visual>
      <origin rpy="0 0 0" xyz="0 0 0"/>
      <geometry>
        <mesh filename="file:///home/tengf/qrb_ros_simulation/install/qrb_ros_sim_description/share/qrb_ros_sim_description/meshes/gemini335_336/camera_infra2_optical_frame.STL"/>
      </geometry>
      <material name="">
        <color rgba="0.501960784313725 0.250980392156863 0.250980392156863 1"/>
      </material>
    </visual>
    <collision>
      <origin rpy="0 0 0" xyz="0 0 0"/>
      <geometry>
        <mesh filename="file:///home/tengf/qrb_ros_simulation/install/qrb_ros_sim_description/share/qrb_ros_sim_description/meshes/gemini335_336/camera_infra2_optical_frame.STL"/>
      </geometry>
    </collision>
  </link>
  <joint name="camera_infra2_optical_joint" type="fixed">
    <origin rpy="-1.5707963267949 0 -1.5707963267949" xyz="0.01587 0.025 0.0125"/>
    <parent link="camera_bottom_screw_frame"/>
    <child link="camera_infra2_optical_frame"/>
    <axis xyz="0 0 0"/>
  </joint>
  <link name="camera_color_frame">
    <inertial>
      <origin rpy="0 0 0" xyz="-0.00177079701156752 -2.20101367029782E-07 2.09893364599916E-07"/>
      <mass value="0.000139779365329478"/>
      <inertia ixx="6.69130695410276E-10" ixy="-1.53742421247628E-13" ixz="-2.28137695085953E-14" iyy="6.11277085561398E-10" iyz="4.18921196289284E-14" izz="6.11078036871936E-10"/>
    </inertial>
    <visual>
      <origin rpy="0 0 0" xyz="0 0 0"/>
      <geometry>
        <mesh filename="file:///home/tengf/qrb_ros_simulation/install/qrb_ros_sim_description/share/qrb_ros_sim_description/meshes/gemini335_336/camera_color_frame.STL"/>
      </geometry>
      <material name="">
        <color rgba="0.501960784313725 0.250980392156863 0.250980392156863 1"/>
      </material>
    </visual>
    <collision>
      <origin rpy="0 0 0" xyz="0 0 0"/>
      <geometry>
        <mesh filename="file:///home/tengf/qrb_ros_simulation/install/qrb_ros_sim_description/share/qrb_ros_sim_description/meshes/gemini335_336/camera_color_frame.STL"/>
      </geometry>
    </collision>
  </link>
  <joint name="camera_color_joint" type="fixed">
    <origin rpy="0 0 0" xyz="0.017533 0.010995 0.012505"/>
    <parent link="camera_bottom_screw_frame"/>
    <child link="camera_color_frame"/>
    <axis xyz="0 0 0"/>
  </joint>
  <link name="camera_color_optical_frame">
    <inertial>
      <origin rpy="0 0 0" xyz="2.20101367029782E-07 -2.09893364599916E-07 -0.00177079701156752"/>
      <mass value="0.000139779365329478"/>
      <inertia ixx="6.11277085561398E-10" ixy="4.18921196289284E-14" ixz="1.53742421247628E-13" iyy="6.11078036871936E-10" iyz="2.28137695085953E-14" izz="6.69130695410276E-10"/>
    </inertial>
    <visual>
      <origin rpy="0 0 0" xyz="0 0 0"/>
      <geometry>
        <mesh filename="file:///home/tengf/qrb_ros_simulation/install/qrb_ros_sim_description/share/qrb_ros_sim_description/meshes/gemini335_336/camera_color_optical_frame.STL"/>
      </geometry>
      <material name="">
        <color rgba="0.501960784313725 0.250980392156863 0.250980392156863 1"/>
      </material>
    </visual>
    <collision>
      <origin rpy="0 0 0" xyz="0 0 0"/>
      <geometry>
        <mesh filename="file:///home/tengf/qrb_ros_simulation/install/qrb_ros_sim_description/share/qrb_ros_sim_description/meshes/gemini335_336/camera_color_optical_frame.STL"/>
      </geometry>
    </collision>
  </link>
  <joint name="camera_color_optical_joint" type="fixed">
    <origin rpy="-1.5707963267949 0 -1.5707963267949" xyz="0.017533 0.010995 0.012505"/>
    <parent link="camera_bottom_screw_frame"/>
    <child link="camera_color_optical_frame"/>
    <axis xyz="0 0 0"/>
  </joint>
  <link name="camera_depth_frame">
    <inertial>
      <origin rpy="0 0 0" xyz="-0.00158020887627678 -1.52683853338331E-08 -1.48608003051662E-07"/>
      <mass value="0.000453168790516429"/>
      <inertia ixx="4.34108781911687E-09" ixy="-3.69655517006982E-13" ixz="-1.45486421873185E-13" iyy="4.84012226840139E-09" iyz="1.92888940614707E-14" izz="4.84044260907388E-09"/>
    </inertial>
    <visual>
      <origin rpy="0 0 0" xyz="0 0 0"/>
      <geometry>
        <mesh filename="file:///home/tengf/qrb_ros_simulation/install/qrb_ros_sim_description/share/qrb_ros_sim_description/meshes/gemini335_336/camera_depth_frame.STL"/>
      </geometry>
      <material name="">
        <color rgba="0.501960784313725 0.250980392156863 0.250980392156863 1"/>
      </material>
    </visual>
    <collision>
      <origin rpy="0 0 0" xyz="0 0 0"/>
      <geometry>
        <mesh filename="file:///home/tengf/qrb_ros_simulation/install/qrb_ros_sim_description/share/qrb_ros_sim_description/meshes/gemini335_336/camera_depth_frame.STL"/>
      </geometry>
    </collision>
  </link>
  <joint name="camera_depth_joint" type="fixed">
    <origin rpy="0 0 0" xyz="0.01587 -0.025 0.0125"/>
    <parent link="camera_bottom_screw_frame"/>
    <child link="camera_depth_frame"/>
    <axis xyz="0 0 0"/>
  </joint>
  <link name="camera_depth_optical_frame">
    <inertial>
      <origin rpy="0 0 0" xyz="1.52683853338331E-08 1.4860800305165E-07 -0.00158020887627678"/>
      <mass value="0.000453168790516429"/>
      <inertia ixx="4.84012226840139E-09" ixy="1.9288894061467E-14" ixz="3.69655517006976E-13" iyy="4.84044260907388E-09" iyz="1.454864218732E-13" izz="4.34108781911687E-09"/>
    </inertial>
    <visual>
      <origin rpy="0 0 0" xyz="0 0 0"/>
      <geometry>
        <mesh filename="file:///home/tengf/qrb_ros_simulation/install/qrb_ros_sim_description/share/qrb_ros_sim_description/meshes/gemini335_336/camera_depth_optical_frame.STL"/>
      </geometry>
      <material name="">
        <color rgba="0.501960784313725 0.250980392156863 0.250980392156863 1"/>
      </material>
    </visual>
    <collision>
      <origin rpy="0 0 0" xyz="0 0 0"/>
      <geometry>
        <mesh filename="file:///home/tengf/qrb_ros_simulation/install/qrb_ros_sim_description/share/qrb_ros_sim_description/meshes/gemini335_336/camera_depth_optical_frame.STL"/>
      </geometry>
    </collision>
  </link>
  <joint name="camera_depth_optical_joint" type="fixed">
    <origin rpy="-1.5707963267949 0 -1.5707963267949" xyz="0.01587 -0.025 0.0125"/>
    <parent link="camera_bottom_screw_frame"/>
    <child link="camera_depth_optical_frame"/>
    <axis xyz="0 0 0"/>
  </joint>
  <joint name="arm_camera_joint" type="fixed">
    <origin rpy="3.1415926 -1.570796 0" xyz="0.080 0 0.015"/>
    <parent link="link6"/>
    <child link="camera_link"/>
  </joint>
  <link name="world"/>
  <joint name="arm_virtual_joint" type="fixed">
    <parent link="world"/>
    <child link="arm_base_link"/>
  </joint>
  <!-- ros2_control -->
  <ros2_control name="GazeboSimSystem" type="system">
    <hardware>
      <plugin>gz_ros2_control/GazeboSimSystem</plugin>
    </hardware>
    <joint name="joint1">
      <command_interface name="position"/>
      <state_interface name="position">
        <param name="initial_value">0</param>
      </state_interface>
      <state_interface name="velocity"/>
    </joint>
    <joint name="joint2">
      <command_interface name="position"/>
      <state_interface name="position">
        <param name="initial_value">1.2967269</param>
      </state_interface>
      <state_interface name="velocity"/>
    </joint>
    <joint name="joint3">
      <command_interface name="position"/>
      <state_interface name="position">
        <param name="initial_value">-1.8044695</param>
      </state_interface>
      <state_interface name="velocity"/>
    </joint>
    <joint name="joint4">
      <command_interface name="position"/>
      <state_interface name="position">
        <param name="initial_value">-0.0600454</param>
      </state_interface>
      <state_interface name="velocity"/>
    </joint>
    <joint name="joint5">
      <command_interface name="position"/>
      <state_interface name="position">
        <param name="initial_value">-1.09238748</param>
      </state_interface>
      <state_interface name="velocity"/>
    </joint>
    <joint name="joint6">
      <command_interface name="position"/>
      <state_interface name="position">
        <param name="initial_value">0.0157049996</param>
      </state_interface>
      <state_interface name="velocity"/>
    </joint>
    <joint name="joint01">
      <command_interface name="position"/>
      <state_interface name="position">
        <param name="initial_value">0.1</param>
      </state_interface>
      <state_interface name="velocity"/>
    </joint>
    <joint name="joint11">
      <command_interface name="position"/>
      <state_interface name="position">
        <param name="initial_value">-0.1</param>
      </state_interface>
      <state_interface name="velocity"/>
    </joint>
    <joint name="joint02">
      <command_interface name="position"/>
      <state_interface name="position">
        <param name="initial_value">-0.1</param>
      </state_interface>
      <state_interface name="velocity"/>
    </joint>
    <joint name="joint22">
      <command_interface name="position"/>
      <state_interface name="position">
        <param name="initial_value">0.1</param>
      </state_interface>
      <state_interface name="velocity"/>
    </joint>
  </ros2_control>
  <!-- ros2_control plugin -->
  <gazebo>
    <plugin filename="libgz_ros2_control-system.so" name="gz_ros2_control::GazeboSimROS2ControlPlugin">
      <ros>
        <namespace></namespace>
      </ros>
      <parameters>/home/tengf/qrb_ros_simulation/install/qrb_ros_sim_gazebo/share/qrb_ros_sim_gazebo/config/params/rml_63_ros2_controllers.yaml</parameters>
      <robot_param>robot_description</robot_param>
      <robot_param_node>robot_state_publisher</robot_param_node>
    </plugin>
  </gazebo>
</robot>
